Workbook

Sheet READ ME
B2: How Computers Spot Similar Sentences
B3: MinHash + Locality Sensitive Hashing (LSH), fully worked on 3 tiny sentences
B5: The problem, in plain words
B6: Imagine you have millions of sentences and you want to find near-duplicates. Comparing every pair is far too slow. The trick in this workbook: turn each sentence into a tiny 'fingerprint', then sort fingerprints into buckets so lookalikes land in the SAME bucket - and you only ever compare things that share a bucket.
B10: Our three example sentences
B11: Sentence 1 | C11: "the cat sat on the mat" | E11: the original
B12: Sentence 2 | C12: "the cat sat on a mat" | E12: near-duplicate: one word changed
B13: Sentence 3 | C13: "dogs love long walks" | E13: completely unrelated
B15: The 4-step pipeline (one sheet per step)
B16: 1 Shingling | C16: Chop each sentence into overlapping 2-word pieces ('shingles').
B17: 2 True Similarity | C17: Score overlap with the Jaccard formula: shared / total. This is our ground truth.
B18: 3 MinHash | C18: Shrink each sentence to an 8-number fingerprint using random shuffles.
B19: 4 LSH Buckets | C19: Cut fingerprints into bands; matching bands = same bucket = worth comparing.
B21: How to read the cells
B22: Blue text | C22: means raw data you may edit (sentences, shingles, shuffle numbers)
B23: Black text | C23: means a LIVE formula. Click any black number to see the actual math in the formula bar.
B24: Green cells | C24: means a match / same-bucket moment. This is where the magic is visible.
B26: Everything downstream recalculates if you change the data - the whole point is that the math is real.

Sheet 1 Shingling
B2: Step 1 - Shingling: chop sentences into overlapping pieces
B3: Slide a 2-word window along each sentence, one word at a time. Each stop produces one 'shingle'. Similar sentences end up sharing many shingles; unrelated ones share none.
B6: Sentence 1 | C6: "the cat sat on the mat"
B7: Window stop | C7: Words taken | D7: Shingle produced
B8: stop 1 | C8: words 1-2 | D8: the cat
B9: stop 2 | C9: words 2-3 | D9: cat sat
B10: stop 3 | C10: words 3-4 | D10: sat on
B11: stop 4 | C11: words 4-5 | D11: on the
B12: stop 5 | C12: words 5-6 | D12: the mat
B14: Sentence 2 | C14: "the cat sat on a mat"
B15: Window stop | C15: Words taken | D15: Shingle produced
B16: stop 1 | C16: words 1-2 | D16: the cat
B17: stop 2 | C17: words 2-3 | D17: cat sat
B18: stop 3 | C18: words 3-4 | D18: sat on
B19: stop 4 | C19: words 4-5 | D19: on a
B20: stop 5 | C20: words 5-6 | D20: a mat
B22: Sentence 3 | C22: "dogs love long walks"
B23: Window stop | C23: Words taken | D23: Shingle produced
B24: stop 1 | C24: words 1-2 | D24: dogs love
B25: stop 2 | C25: words 2-3 | D25: love long
B26: stop 3 | C26: words 3-4 | D26: long walks
B28: Notice: sentences 1 and 2 share their first three shingles - shingling has turned 'these sentences look alike' into a countable fact.

Sheet 2 True Similarity
B2: Step 2 - The 1/0 table and the true Jaccard similarity
B3: List every distinct shingle from Step 1 (the 'vocabulary'). For each sentence, mark 1 if it contains that shingle, else 0. Every 1/0 below is a live COUNTIF formula reading Step 1.
B6: Shingle (vocabulary) | C6: In S1? | D6: In S2? | E6: In S3?
B7: the cat | C7: =COUNTIF('1 Shingling'!$D$8:$D$12,$B7) -> 1 | D7: =COUNTIF('1 Shingling'!$D$16:$D$20,$B7) -> 1 | E7: =COUNTIF('1 Shingling'!$D$24:$D$26,$B7) -> 0
B8: cat sat | C8: =COUNTIF('1 Shingling'!$D$8:$D$12,$B8) -> 1 | D8: =COUNTIF('1 Shingling'!$D$16:$D$20,$B8) -> 1 | E8: =COUNTIF('1 Shingling'!$D$24:$D$26,$B8) -> 0
B9: sat on | C9: =COUNTIF('1 Shingling'!$D$8:$D$12,$B9) -> 1 | D9: =COUNTIF('1 Shingling'!$D$16:$D$20,$B9) -> 1 | E9: =COUNTIF('1 Shingling'!$D$24:$D$26,$B9) -> 0
B10: on the | C10: =COUNTIF('1 Shingling'!$D$8:$D$12,$B10) -> 1 | D10: =COUNTIF('1 Shingling'!$D$16:$D$20,$B10) -> 0 | E10: =COUNTIF('1 Shingling'!$D$24:$D$26,$B10) -> 0
B11: the mat | C11: =COUNTIF('1 Shingling'!$D$8:$D$12,$B11) -> 1 | D11: =COUNTIF('1 Shingling'!$D$16:$D$20,$B11) -> 0 | E11: =COUNTIF('1 Shingling'!$D$24:$D$26,$B11) -> 0
B12: on a | C12: =COUNTIF('1 Shingling'!$D$8:$D$12,$B12) -> 0 | D12: =COUNTIF('1 Shingling'!$D$16:$D$20,$B12) -> 1 | E12: =COUNTIF('1 Shingling'!$D$24:$D$26,$B12) -> 0
B13: a mat | C13: =COUNTIF('1 Shingling'!$D$8:$D$12,$B13) -> 0 | D13: =COUNTIF('1 Shingling'!$D$16:$D$20,$B13) -> 1 | E13: =COUNTIF('1 Shingling'!$D$24:$D$26,$B13) -> 0
B14: dogs love | C14: =COUNTIF('1 Shingling'!$D$8:$D$12,$B14) -> 0 | D14: =COUNTIF('1 Shingling'!$D$16:$D$20,$B14) -> 0 | E14: =COUNTIF('1 Shingling'!$D$24:$D$26,$B14) -> 1
B15: love long | C15: =COUNTIF('1 Shingling'!$D$8:$D$12,$B15) -> 0 | D15: =COUNTIF('1 Shingling'!$D$16:$D$20,$B15) -> 0 | E15: =COUNTIF('1 Shingling'!$D$24:$D$26,$B15) -> 1
B16: long walks | C16: =COUNTIF('1 Shingling'!$D$8:$D$12,$B16) -> 0 | D16: =COUNTIF('1 Shingling'!$D$16:$D$20,$B16) -> 0 | E16: =COUNTIF('1 Shingling'!$D$24:$D$26,$B16) -> 1
B18: Now the actual similarity math, straight from the 1/0 columns:
B19: Pair | C19: Shared shingles | D19: Total distinct | E19: Jaccard = shared/total
B20: S1 vs S2 | C20: =SUMPRODUCT($C$7:$C$16*$D$7:$D$16) -> 3 | D20: =SUMPRODUCT(--(($C$7:$C$16+$D$7:$D$16)>0)) -> 7 | E20: =C20/D20 -> 0.42857143
B21: S1 vs S3 | C21: =SUMPRODUCT($C$7:$C$16*$E$7:$E$16) -> 0 | D21: =SUMPRODUCT(--(($C$7:$C$16+$E$7:$E$16)>0)) -> 8 | E21: =C21/D21 -> 0
B22: S2 vs S3 | C22: =SUMPRODUCT($D$7:$D$16*$E$7:$E$16) -> 0 | D22: =SUMPRODUCT(--(($D$7:$D$16+$E$7:$E$16)>0)) -> 8 | E22: =C22/D22 -> 0
B24: Read S1 vs S2 as: 3 shared shingles out of 7 distinct ones = 43%. That 43% is the ground truth the fingerprints in Step 3 will try to guess without ever seeing this table.

Sheet 3a The Queue
B2: Step 3a - The shuffle, seen as a QUEUE (read this before the rank tables)
B3: A 'shuffle' just means: make all 10 shingles stand in one line, in random order. Then each sentence walks down the line from the front and stops at the FIRST shingle it owns. That stopping position IS the sentence's MinHash number. Nothing else is happening.
B6: Queue for Shuffle #1 | H6: Queue for Shuffle #2
B7: Position in line | C7: Who is standing here? | D7: S1 owns it? | E7: S2 owns it? | F7: S3 owns it? | H7: Position in line | I7: Who is standing here? | J7: S1 owns it? | K7: S2 owns it? | L7: S3 owns it?
B8: 1 | C8: =INDEX('2 True Similarity'!$B$7:$B$16,MATCH(B8+0,'3 MinHash'!$F$9:$F$18,0)) -> on a | D8: =IF(INDEX('2 True Similarity'!$C$7:$C$16,MATCH(B8+0,'3 MinHash'!$F$9:$F$18,0))=1,"YES","-") -> - | E8: =IF(INDEX('2 True Similarity'!$D$7:$D$16,MATCH(B8+0,'3 MinHash'!$F$9:$F$18,0))=1,"YES","-") -> YES | F8: =IF(INDEX('2 True Similarity'!$E$7:$E$16,MATCH(B8+0,'3 MinHash'!$F$9:$F$18,0))=1,"YES","-") -> - | H8: 1 | I8: =INDEX('2 True Similarity'!$B$7:$B$16,MATCH(H8+0,'3 MinHash'!$C$27:$L$27,0)) -> dogs love | J8: =IF(INDEX('2 True Similarity'!$C$7:$C$16,MATCH(H8+0,'3 MinHash'!$C$27:$L$27,0))=1,"YES","-") -> - | K8: =IF(INDEX('2 True Similarity'!$D$7:$D$16,MATCH(H8+0,'3 MinHash'!$C$27:$L$27,0))=1,"YES","-") -> - | L8: =IF(INDEX('2 True Similarity'!$E$7:$E$16,MATCH(H8+0,'3 MinHash'!$C$27:$L$27,0))=1,"YES","-") -> YES
B9: 2 | C9: =INDEX('2 True Similarity'!$B$7:$B$16,MATCH(B9+0,'3 MinHash'!$F$9:$F$18,0)) -> sat on | D9: =IF(INDEX('2 True Similarity'!$C$7:$C$16,MATCH(B9+0,'3 MinHash'!$F$9:$F$18,0))=1,"YES","-") -> YES | E9: =IF(INDEX('2 True Similarity'!$D$7:$D$16,MATCH(B9+0,'3 MinHash'!$F$9:$F$18,0))=1,"YES","-") -> YES | F9: =IF(INDEX('2 True Similarity'!$E$7:$E$16,MATCH(B9+0,'3 MinHash'!$F$9:$F$18,0))=1,"YES","-") -> - | H9: 2 | I9: =INDEX('2 True Similarity'!$B$7:$B$16,MATCH(H9+0,'3 MinHash'!$C$27:$L$27,0)) -> the cat | J9: =IF(INDEX('2 True Similarity'!$C$7:$C$16,MATCH(H9+0,'3 MinHash'!$C$27:$L$27,0))=1,"YES","-") -> YES | K9: =IF(INDEX('2 True Similarity'!$D$7:$D$16,MATCH(H9+0,'3 MinHash'!$C$27:$L$27,0))=1,"YES","-") -> YES | L9: =IF(INDEX('2 True Similarity'!$E$7:$E$16,MATCH(H9+0,'3 MinHash'!$C$27:$L$27,0))=1,"YES","-") -> -
B10: 3 | C10: =INDEX('2 True Similarity'!$B$7:$B$16,MATCH(B10+0,'3 MinHash'!$F$9:$F$18,0)) -> love long | D10: =IF(INDEX('2 True Similarity'!$C$7:$C$16,MATCH(B10+0,'3 MinHash'!$F$9:$F$18,0))=1,"YES","-") -> - | E10: =IF(INDEX('2 True Similarity'!$D$7:$D$16,MATCH(B10+0,'3 MinHash'!$F$9:$F$18,0))=1,"YES","-") -> - | F10: =IF(INDEX('2 True Similarity'!$E$7:$E$16,MATCH(B10+0,'3 MinHash'!$F$9:$F$18,0))=1,"YES","-") -> YES | H10: 3 | I10: =INDEX('2 True Similarity'!$B$7:$B$16,MATCH(H10+0,'3 MinHash'!$C$27:$L$27,0)) -> cat sat | J10: =IF(INDEX('2 True Similarity'!$C$7:$C$16,MATCH(H10+0,'3 MinHash'!$C$27:$L$27,0))=1,"YES","-") -> YES | K10: =IF(INDEX('2 True Similarity'!$D$7:$D$16,MATCH(H10+0,'3 MinHash'!$C$27:$L$27,0))=1,"YES","-") -> YES | L10: =IF(INDEX('2 True Similarity'!$E$7:$E$16,MATCH(H10+0,'3 MinHash'!$C$27:$L$27,0))=1,"YES","-") -> -
B11: 4 | C11: =INDEX('2 True Similarity'!$B$7:$B$16,MATCH(B11+0,'3 MinHash'!$F$9:$F$18,0)) -> cat sat | D11: =IF(INDEX('2 True Similarity'!$C$7:$C$16,MATCH(B11+0,'3 MinHash'!$F$9:$F$18,0))=1,"YES","-") -> YES | E11: =IF(INDEX('2 True Similarity'!$D$7:$D$16,MATCH(B11+0,'3 MinHash'!$F$9:$F$18,0))=1,"YES","-") -> YES | F11: =IF(INDEX('2 True Similarity'!$E$7:$E$16,MATCH(B11+0,'3 MinHash'!$F$9:$F$18,0))=1,"YES","-") -> - | H11: 4 | I11: =INDEX('2 True Similarity'!$B$7:$B$16,MATCH(H11+0,'3 MinHash'!$C$27:$L$27,0)) -> love long | J11: =IF(INDEX('2 True Similarity'!$C$7:$C$16,MATCH(H11+0,'3 MinHash'!$C$27:$L$27,0))=1,"YES","-") -> - | K11: =IF(INDEX('2 True Similarity'!$D$7:$D$16,MATCH(H11+0,'3 MinHash'!$C$27:$L$27,0))=1,"YES","-") -> - | L11: =IF(INDEX('2 True Similarity'!$E$7:$E$16,MATCH(H11+0,'3 MinHash'!$C$27:$L$27,0))=1,"YES","-") -> YES
B12: 5 | C12: =INDEX('2 True Similarity'!$B$7:$B$16,MATCH(B12+0,'3 MinHash'!$F$9:$F$18,0)) -> on the | D12: =IF(INDEX('2 True Similarity'!$C$7:$C$16,MATCH(B12+0,'3 MinHash'!$F$9:$F$18,0))=1,"YES","-") -> YES | E12: =IF(INDEX('2 True Similarity'!$D$7:$D$16,MATCH(B12+0,'3 MinHash'!$F$9:$F$18,0))=1,"YES","-") -> - | F12: =IF(INDEX('2 True Similarity'!$E$7:$E$16,MATCH(B12+0,'3 MinHash'!$F$9:$F$18,0))=1,"YES","-") -> - | H12: 5 | I12: =INDEX('2 True Similarity'!$B$7:$B$16,MATCH(H12+0,'3 MinHash'!$C$27:$L$27,0)) -> sat on | J12: =IF(INDEX('2 True Similarity'!$C$7:$C$16,MATCH(H12+0,'3 MinHash'!$C$27:$L$27,0))=1,"YES","-") -> YES | K12: =IF(INDEX('2 True Similarity'!$D$7:$D$16,MATCH(H12+0,'3 MinHash'!$C$27:$L$27,0))=1,"YES","-") -> YES | L12: =IF(INDEX('2 True Similarity'!$E$7:$E$16,MATCH(H12+0,'3 MinHash'!$C$27:$L$27,0))=1,"YES","-") -> -
B13: 6 | C13: =INDEX('2 True Similarity'!$B$7:$B$16,MATCH(B13+0,'3 MinHash'!$F$9:$F$18,0)) -> long walks | D13: =IF(INDEX('2 True Similarity'!$C$7:$C$16,MATCH(B13+0,'3 MinHash'!$F$9:$F$18,0))=1,"YES","-") -> - | E13: =IF(INDEX('2 True Similarity'!$D$7:$D$16,MATCH(B13+0,'3 MinHash'!$F$9:$F$18,0))=1,"YES","-") -> - | F13: =IF(INDEX('2 True Similarity'!$E$7:$E$16,MATCH(B13+0,'3 MinHash'!$F$9:$F$18,0))=1,"YES","-") -> YES | H13: 6 | I13: =INDEX('2 True Similarity'!$B$7:$B$16,MATCH(H13+0,'3 MinHash'!$C$27:$L$27,0)) -> the mat | J13: =IF(INDEX('2 True Similarity'!$C$7:$C$16,MATCH(H13+0,'3 MinHash'!$C$27:$L$27,0))=1,"YES","-") -> YES | K13: =IF(INDEX('2 True Similarity'!$D$7:$D$16,MATCH(H13+0,'3 MinHash'!$C$27:$L$27,0))=1,"YES","-") -> - | L13: =IF(INDEX('2 True Similarity'!$E$7:$E$16,MATCH(H13+0,'3 MinHash'!$C$27:$L$27,0))=1,"YES","-") -> -
B14: 7 | C14: =INDEX('2 True Similarity'!$B$7:$B$16,MATCH(B14+0,'3 MinHash'!$F$9:$F$18,0)) -> dogs love | D14: =IF(INDEX('2 True Similarity'!$C$7:$C$16,MATCH(B14+0,'3 MinHash'!$F$9:$F$18,0))=1,"YES","-") -> - | E14: =IF(INDEX('2 True Similarity'!$D$7:$D$16,MATCH(B14+0,'3 MinHash'!$F$9:$F$18,0))=1,"YES","-") -> - | F14: =IF(INDEX('2 True Similarity'!$E$7:$E$16,MATCH(B14+0,'3 MinHash'!$F$9:$F$18,0))=1,"YES","-") -> YES | H14: 7 | I14: =INDEX('2 True Similarity'!$B$7:$B$16,MATCH(H14+0,'3 MinHash'!$C$27:$L$27,0)) -> on the | J14: =IF(INDEX('2 True Similarity'!$C$7:$C$16,MATCH(H14+0,'3 MinHash'!$C$27:$L$27,0))=1,"YES","-") -> YES | K14: =IF(INDEX('2 True Similarity'!$D$7:$D$16,MATCH(H14+0,'3 MinHash'!$C$27:$L$27,0))=1,"YES","-") -> - | L14: =IF(INDEX('2 True Similarity'!$E$7:$E$16,MATCH(H14+0,'3 MinHash'!$C$27:$L$27,0))=1,"YES","-") -> -
B15: 8 | C15: =INDEX('2 True Similarity'!$B$7:$B$16,MATCH(B15+0,'3 MinHash'!$F$9:$F$18,0)) -> the mat | D15: =IF(INDEX('2 True Similarity'!$C$7:$C$16,MATCH(B15+0,'3 MinHash'!$F$9:$F$18,0))=1,"YES","-") -> YES | E15: =IF(INDEX('2 True Similarity'!$D$7:$D$16,MATCH(B15+0,'3 MinHash'!$F$9:$F$18,0))=1,"YES","-") -> - | F15: =IF(INDEX('2 True Similarity'!$E$7:$E$16,MATCH(B15+0,'3 MinHash'!$F$9:$F$18,0))=1,"YES","-") -> - | H15: 8 | I15: =INDEX('2 True Similarity'!$B$7:$B$16,MATCH(H15+0,'3 MinHash'!$C$27:$L$27,0)) -> a mat | J15: =IF(INDEX('2 True Similarity'!$C$7:$C$16,MATCH(H15+0,'3 MinHash'!$C$27:$L$27,0))=1,"YES","-") -> - | K15: =IF(INDEX('2 True Similarity'!$D$7:$D$16,MATCH(H15+0,'3 MinHash'!$C$27:$L$27,0))=1,"YES","-") -> YES | L15: =IF(INDEX('2 True Similarity'!$E$7:$E$16,MATCH(H15+0,'3 MinHash'!$C$27:$L$27,0))=1,"YES","-") -> -
B16: 9 | C16: =INDEX('2 True Similarity'!$B$7:$B$16,MATCH(B16+0,'3 MinHash'!$F$9:$F$18,0)) -> the cat | D16: =IF(INDEX('2 True Similarity'!$C$7:$C$16,MATCH(B16+0,'3 MinHash'!$F$9:$F$18,0))=1,"YES","-") -> YES | E16: =IF(INDEX('2 True Similarity'!$D$7:$D$16,MATCH(B16+0,'3 MinHash'!$F$9:$F$18,0))=1,"YES","-") -> YES | F16: =IF(INDEX('2 True Similarity'!$E$7:$E$16,MATCH(B16+0,'3 MinHash'!$F$9:$F$18,0))=1,"YES","-") -> - | H16: 9 | I16: =INDEX('2 True Similarity'!$B$7:$B$16,MATCH(H16+0,'3 MinHash'!$C$27:$L$27,0)) -> long walks | J16: =IF(INDEX('2 True Similarity'!$C$7:$C$16,MATCH(H16+0,'3 MinHash'!$C$27:$L$27,0))=1,"YES","-") -> - | K16: =IF(INDEX('2 True Similarity'!$D$7:$D$16,MATCH(H16+0,'3 MinHash'!$C$27:$L$27,0))=1,"YES","-") -> - | L16: =IF(INDEX('2 True Similarity'!$E$7:$E$16,MATCH(H16+0,'3 MinHash'!$C$27:$L$27,0))=1,"YES","-") -> YES
B17: 10 | C17: =INDEX('2 True Similarity'!$B$7:$B$16,MATCH(B17+0,'3 MinHash'!$F$9:$F$18,0)) -> a mat | D17: =IF(INDEX('2 True Similarity'!$C$7:$C$16,MATCH(B17+0,'3 MinHash'!$F$9:$F$18,0))=1,"YES","-") -> - | E17: =IF(INDEX('2 True Similarity'!$D$7:$D$16,MATCH(B17+0,'3 MinHash'!$F$9:$F$18,0))=1,"YES","-") -> YES | F17: =IF(INDEX('2 True Similarity'!$E$7:$E$16,MATCH(B17+0,'3 MinHash'!$F$9:$F$18,0))=1,"YES","-") -> - | H17: 10 | I17: =INDEX('2 True Similarity'!$B$7:$B$16,MATCH(H17+0,'3 MinHash'!$C$27:$L$27,0)) -> on a | J17: =IF(INDEX('2 True Similarity'!$C$7:$C$16,MATCH(H17+0,'3 MinHash'!$C$27:$L$27,0))=1,"YES","-") -> - | K17: =IF(INDEX('2 True Similarity'!$D$7:$D$16,MATCH(H17+0,'3 MinHash'!$C$27:$L$27,0))=1,"YES","-") -> YES | L17: =IF(INDEX('2 True Similarity'!$E$7:$E$16,MATCH(H17+0,'3 MinHash'!$C$27:$L$27,0))=1,"YES","-") -> -
B18: MinHash = position of the first YES: | D18: =MATCH("YES",D8:D17,0) -> 2 | E18: =MATCH("YES",E8:E17,0) -> 1 | F18: =MATCH("YES",F8:F17,0) -> 3 | H18: MinHash = position of the first YES: | J18: =MATCH("YES",J8:J17,0) -> 2 | K18: =MATCH("YES",K8:K17,0) -> 2 | L18: =MATCH("YES",L8:L17,0) -> 1
B20: Walk Shuffle #1 with your finger: position 1 is 'on a' - only Sentence 2 owns it, so S2 stops immediately: MinHash 1. S1 keeps walking and stops at position 2 ('sat on'): MinHash 2. Different stops = no match. Now walk Shuffle #2: position 1 is 'dogs love' (S3 stops), position 2 is 'the cat' - owned by BOTH cat sentences, so S1 and S2 stop together: both get MinHash 2. A match happens exactly when the first-reachable shingle is SHARED.
B24: That is all a 'rank' ever was: the rank tables on the next sheet are these same queues written sideways (rank 4 = 'stands 4th in line'), and 'MIN of ranks' = 'first of your shingles to appear'. Same walk, written as arithmetic so Excel can do 8 of them at once.

Sheet 3 MinHash
B2: Step 3 - MinHash: shrink each sentence to an 8-number fingerprint
B3: Game: shuffle the 10 vocabulary shingles into a random order (each shingle gets a rank 1-10). A sentence's MinHash = the SMALLEST rank among the shingles it contains - i.e. whichever of its shingles comes first in the shuffle. Two sentences get the SAME MinHash exactly when the shuffle's overall front-runner is a shingle they share.
B7: One shuffle in slow motion (Shuffle #1)
B8: Shingle | C8: In S1? | D8: In S2? | E8: In S3? | F8: Shuffle rank | G8: Rank if in S1 | H8: Rank if in S2 | I8: Rank if in S3
B9: the cat | C9: ='2 True Similarity'!C7 -> 1 | D9: ='2 True Similarity'!D7 -> 1 | E9: ='2 True Similarity'!E7 -> 0 | F9: 9 | G9: =IF(C9=1,$F9,"") -> 9 | H9: =IF(D9=1,$F9,"") -> 9 | I9: =IF(E9=1,$F9,"")
B10: cat sat | C10: ='2 True Similarity'!C8 -> 1 | D10: ='2 True Similarity'!D8 -> 1 | E10: ='2 True Similarity'!E8 -> 0 | F10: 4 | G10: =IF(C10=1,$F10,"") -> 4 | H10: =IF(D10=1,$F10,"") -> 4 | I10: =IF(E10=1,$F10,"")
B11: sat on | C11: ='2 True Similarity'!C9 -> 1 | D11: ='2 True Similarity'!D9 -> 1 | E11: ='2 True Similarity'!E9 -> 0 | F11: 2 | G11: =IF(C11=1,$F11,"") -> 2 | H11: =IF(D11=1,$F11,"") -> 2 | I11: =IF(E11=1,$F11,"")
B12: on the | C12: ='2 True Similarity'!C10 -> 1 | D12: ='2 True Similarity'!D10 -> 0 | E12: ='2 True Similarity'!E10 -> 0 | F12: 5 | G12: =IF(C12=1,$F12,"") -> 5 | H12: =IF(D12=1,$F12,"") | I12: =IF(E12=1,$F12,"")
B13: the mat | C13: ='2 True Similarity'!C11 -> 1 | D13: ='2 True Similarity'!D11 -> 0 | E13: ='2 True Similarity'!E11 -> 0 | F13: 8 | G13: =IF(C13=1,$F13,"") -> 8 | H13: =IF(D13=1,$F13,"") | I13: =IF(E13=1,$F13,"")
B14: on a | C14: ='2 True Similarity'!C12 -> 0 | D14: ='2 True Similarity'!D12 -> 1 | E14: ='2 True Similarity'!E12 -> 0 | F14: 1 | G14: =IF(C14=1,$F14,"") | H14: =IF(D14=1,$F14,"") -> 1 | I14: =IF(E14=1,$F14,"")
B15: a mat | C15: ='2 True Similarity'!C13 -> 0 | D15: ='2 True Similarity'!D13 -> 1 | E15: ='2 True Similarity'!E13 -> 0 | F15: 10 | G15: =IF(C15=1,$F15,"") | H15: =IF(D15=1,$F15,"") -> 10 | I15: =IF(E15=1,$F15,"")
B16: dogs love | C16: ='2 True Similarity'!C14 -> 0 | D16: ='2 True Similarity'!D14 -> 0 | E16: ='2 True Similarity'!E14 -> 1 | F16: 7 | G16: =IF(C16=1,$F16,"") | H16: =IF(D16=1,$F16,"") | I16: =IF(E16=1,$F16,"") -> 7
B17: love long | C17: ='2 True Similarity'!C15 -> 0 | D17: ='2 True Similarity'!D15 -> 0 | E17: ='2 True Similarity'!E15 -> 1 | F17: 3 | G17: =IF(C17=1,$F17,"") | H17: =IF(D17=1,$F17,"") | I17: =IF(E17=1,$F17,"") -> 3
B18: long walks | C18: ='2 True Similarity'!C16 -> 0 | D18: ='2 True Similarity'!D16 -> 0 | E18: ='2 True Similarity'!E16 -> 1 | F18: 6 | G18: =IF(C18=1,$F18,"") | H18: =IF(D18=1,$F18,"") | I18: =IF(E18=1,$F18,"") -> 6
B19: MinHash (smallest rank present) | G19: =MIN(G9:G18) -> 2 | H19: =MIN(H9:H18) -> 1 | I19: =MIN(I9:I18) -> 3
B20: Winning shingle | G20: =INDEX($B$9:$B$18,MATCH(G19,G9:G18,0)) -> sat on | H20: =INDEX($B$9:$B$18,MATCH(H19,H9:H18,0)) -> on a | I20: =INDEX($B$9:$B$18,MATCH(I19,I9:I18,0)) -> love long
B21: Here rank 1 belongs to 'on a' - only S2 has it, so S2's MinHash is 1 while S1 must wait for rank 2 ('sat on'). The front-runner was NOT shared, so no match this shuffle. One shuffle = one noisy yes/no vote; now we repeat with 8 different shuffles.
B24: All 8 shuffles - every shingle's rank in each (blue = the random shuffles themselves)
B25: Shuffle | C25: the cat | D25: cat sat | E25: sat on | F25: on the | G25: the mat | H25: on a | I25: a mat | J25: dogs love | K25: love long | L25: long walks
B26: Shuffle 1 | C26: 9 | D26: 4 | E26: 2 | F26: 5 | G26: 8 | H26: 1 | I26: 10 | J26: 7 | K26: 3 | L26: 6
B27: Shuffle 2 | C27: 2 | D27: 3 | E27: 5 | F27: 7 | G27: 6 | H27: 10 | I27: 8 | J27: 1 | K27: 4 | L27: 9
B28: Shuffle 3 | C28: 4 | D28: 6 | E28: 3 | F28: 2 | G28: 8 | H28: 5 | I28: 10 | J28: 1 | K28: 7 | L28: 9
B29: Shuffle 4 | C29: 6 | D29: 3 | E29: 4 | F29: 9 | G29: 5 | H29: 8 | I29: 2 | J29: 1 | K29: 7 | L29: 10
B30: Shuffle 5 | C30: 4 | D30: 6 | E30: 1 | F30: 8 | G30: 7 | H30: 10 | I30: 5 | J30: 2 | K30: 9 | L30: 3
B31: Shuffle 6 | C31: 10 | D31: 3 | E31: 4 | F31: 8 | G31: 7 | H31: 1 | I31: 5 | J31: 9 | K31: 2 | L31: 6
B32: Shuffle 7 | C32: 4 | D32: 1 | E32: 10 | F32: 5 | G32: 2 | H32: 7 | I32: 3 | J32: 9 | K32: 8 | L32: 6
B33: Shuffle 8 | C33: 10 | D33: 1 | E33: 9 | F33: 7 | G33: 4 | H33: 6 | I33: 3 | J33: 8 | K33: 5 | L33: 2
B35: Engine room - 'rank if the sentence contains that shingle' (same IF trick as slow motion)
B36: Sentence 1 | C36: the cat | D36: cat sat | E36: sat on | F36: on the | G36: the mat | H36: on a | I36: a mat | J36: dogs love | K36: love long | L36: long walks
B37: Shuffle 1 | C37: =IF('2 True Similarity'!C7=1,C26,"") -> 9 | D37: =IF('2 True Similarity'!C8=1,D26,"") -> 4 | E37: =IF('2 True Similarity'!C9=1,E26,"") -> 2 | F37: =IF('2 True Similarity'!C10=1,F26,"") -> 5 | G37: =IF('2 True Similarity'!C11=1,G26,"") -> 8 | H37: =IF('2 True Similarity'!C12=1,H26,"") | I37: =IF('2 True Similarity'!C13=1,I26,"") | J37: =IF('2 True Similarity'!C14=1,J26,"") | K37: =IF('2 True Similarity'!C15=1,K26,"") | L37: =IF('2 True Similarity'!C16=1,L26,"")
B38: Shuffle 2 | C38: =IF('2 True Similarity'!C7=1,C27,"") -> 2 | D38: =IF('2 True Similarity'!C8=1,D27,"") -> 3 | E38: =IF('2 True Similarity'!C9=1,E27,"") -> 5 | F38: =IF('2 True Similarity'!C10=1,F27,"") -> 7 | G38: =IF('2 True Similarity'!C11=1,G27,"") -> 6 | H38: =IF('2 True Similarity'!C12=1,H27,"") | I38: =IF('2 True Similarity'!C13=1,I27,"") | J38: =IF('2 True Similarity'!C14=1,J27,"") | K38: =IF('2 True Similarity'!C15=1,K27,"") | L38: =IF('2 True Similarity'!C16=1,L27,"")
B39: Shuffle 3 | C39: =IF('2 True Similarity'!C7=1,C28,"") -> 4 | D39: =IF('2 True Similarity'!C8=1,D28,"") -> 6 | E39: =IF('2 True Similarity'!C9=1,E28,"") -> 3 | F39: =IF('2 True Similarity'!C10=1,F28,"") -> 2 | G39: =IF('2 True Similarity'!C11=1,G28,"") -> 8 | H39: =IF('2 True Similarity'!C12=1,H28,"") | I39: =IF('2 True Similarity'!C13=1,I28,"") | J39: =IF('2 True Similarity'!C14=1,J28,"") | K39: =IF('2 True Similarity'!C15=1,K28,"") | L39: =IF('2 True Similarity'!C16=1,L28,"")
B40: Shuffle 4 | C40: =IF('2 True Similarity'!C7=1,C29,"") -> 6 | D40: =IF('2 True Similarity'!C8=1,D29,"") -> 3 | E40: =IF('2 True Similarity'!C9=1,E29,"") -> 4 | F40: =IF('2 True Similarity'!C10=1,F29,"") -> 9 | G40: =IF('2 True Similarity'!C11=1,G29,"") -> 5 | H40: =IF('2 True Similarity'!C12=1,H29,"") | I40: =IF('2 True Similarity'!C13=1,I29,"") | J40: =IF('2 True Similarity'!C14=1,J29,"") | K40: =IF('2 True Similarity'!C15=1,K29,"") | L40: =IF('2 True Similarity'!C16=1,L29,"")
B41: Shuffle 5 | C41: =IF('2 True Similarity'!C7=1,C30,"") -> 4 | D41: =IF('2 True Similarity'!C8=1,D30,"") -> 6 | E41: =IF('2 True Similarity'!C9=1,E30,"") -> 1 | F41: =IF('2 True Similarity'!C10=1,F30,"") -> 8 | G41: =IF('2 True Similarity'!C11=1,G30,"") -> 7 | H41: =IF('2 True Similarity'!C12=1,H30,"") | I41: =IF('2 True Similarity'!C13=1,I30,"") | J41: =IF('2 True Similarity'!C14=1,J30,"") | K41: =IF('2 True Similarity'!C15=1,K30,"") | L41: =IF('2 True Similarity'!C16=1,L30,"")
B42: Shuffle 6 | C42: =IF('2 True Similarity'!C7=1,C31,"") -> 10 | D42: =IF('2 True Similarity'!C8=1,D31,"") -> 3 | E42: =IF('2 True Similarity'!C9=1,E31,"") -> 4 | F42: =IF('2 True Similarity'!C10=1,F31,"") -> 8 | G42: =IF('2 True Similarity'!C11=1,G31,"") -> 7 | H42: =IF('2 True Similarity'!C12=1,H31,"") | I42: =IF('2 True Similarity'!C13=1,I31,"") | J42: =IF('2 True Similarity'!C14=1,J31,"") | K42: =IF('2 True Similarity'!C15=1,K31,"") | L42: =IF('2 True Similarity'!C16=1,L31,"")
B43: Shuffle 7 | C43: =IF('2 True Similarity'!C7=1,C32,"") -> 4 | D43: =IF('2 True Similarity'!C8=1,D32,"") -> 1 | E43: =IF('2 True Similarity'!C9=1,E32,"") -> 10 | F43: =IF('2 True Similarity'!C10=1,F32,"") -> 5 | G43: =IF('2 True Similarity'!C11=1,G32,"") -> 2 | H43: =IF('2 True Similarity'!C12=1,H32,"") | I43: =IF('2 True Similarity'!C13=1,I32,"") | J43: =IF('2 True Similarity'!C14=1,J32,"") | K43: =IF('2 True Similarity'!C15=1,K32,"") | L43: =IF('2 True Similarity'!C16=1,L32,"")
B44: Shuffle 8 | C44: =IF('2 True Similarity'!C7=1,C33,"") -> 10 | D44: =IF('2 True Similarity'!C8=1,D33,"") -> 1 | E44: =IF('2 True Similarity'!C9=1,E33,"") -> 9 | F44: =IF('2 True Similarity'!C10=1,F33,"") -> 7 | G44: =IF('2 True Similarity'!C11=1,G33,"") -> 4 | H44: =IF('2 True Similarity'!C12=1,H33,"") | I44: =IF('2 True Similarity'!C13=1,I33,"") | J44: =IF('2 True Similarity'!C14=1,J33,"") | K44: =IF('2 True Similarity'!C15=1,K33,"") | L44: =IF('2 True Similarity'!C16=1,L33,"")
B46: Sentence 2 | C46: the cat | D46: cat sat | E46: sat on | F46: on the | G46: the mat | H46: on a | I46: a mat | J46: dogs love | K46: love long | L46: long walks
B47: Shuffle 1 | C47: =IF('2 True Similarity'!D7=1,C26,"") -> 9 | D47: =IF('2 True Similarity'!D8=1,D26,"") -> 4 | E47: =IF('2 True Similarity'!D9=1,E26,"") -> 2 | F47: =IF('2 True Similarity'!D10=1,F26,"") | G47: =IF('2 True Similarity'!D11=1,G26,"") | H47: =IF('2 True Similarity'!D12=1,H26,"") -> 1 | I47: =IF('2 True Similarity'!D13=1,I26,"") -> 10 | J47: =IF('2 True Similarity'!D14=1,J26,"") | K47: =IF('2 True Similarity'!D15=1,K26,"") | L47: =IF('2 True Similarity'!D16=1,L26,"")
B48: Shuffle 2 | C48: =IF('2 True Similarity'!D7=1,C27,"") -> 2 | D48: =IF('2 True Similarity'!D8=1,D27,"") -> 3 | E48: =IF('2 True Similarity'!D9=1,E27,"") -> 5 | F48: =IF('2 True Similarity'!D10=1,F27,"") | G48: =IF('2 True Similarity'!D11=1,G27,"") | H48: =IF('2 True Similarity'!D12=1,H27,"") -> 10 | I48: =IF('2 True Similarity'!D13=1,I27,"") -> 8 | J48: =IF('2 True Similarity'!D14=1,J27,"") | K48: =IF('2 True Similarity'!D15=1,K27,"") | L48: =IF('2 True Similarity'!D16=1,L27,"")
...

Sheet 4 LSH Buckets
B2: Step 4 - LSH: cut fingerprints into bands, and bands become buckets
B3: We never want to compare all pairs. So: chop each 8-number fingerprint into 4 bands of 2 numbers. Each band's pair of numbers is glued into a bucket label. If two sentences produce the SAME label in ANY band, they land in the same bucket and become a 'candidate pair' - only candidates get the full similarity check from Step 2. Everyone else is never compared at all.
B7: Band | C7: Shuffles | E7: S1 bucket label | F7: S2 bucket label | G7: S3 bucket label | H7: S1 & S2 same bucket? | I7: any with S3?
B8: Band 1 | C8: 1 & 2 | E8: ="["&'3 MinHash'!C69&"-"&'3 MinHash'!C70&"]" -> [2-2] | F8: ="["&'3 MinHash'!D69&"-"&'3 MinHash'!D70&"]" -> [1-2] | G8: ="["&'3 MinHash'!E69&"-"&'3 MinHash'!E70&"]" -> [3-1] | H8: =IF(E8=F8,"SAME BUCKET!","-") -> - | I8: =IF(OR(E8=G8,F8=G8),"SAME BUCKET!","-") -> -
B9: Band 2 | C9: 3 & 4 | E9: ="["&'3 MinHash'!C71&"-"&'3 MinHash'!C72&"]" -> [2-3] | F9: ="["&'3 MinHash'!D71&"-"&'3 MinHash'!D72&"]" -> [3-2] | G9: ="["&'3 MinHash'!E71&"-"&'3 MinHash'!E72&"]" -> [1-1] | H9: =IF(E9=F9,"SAME BUCKET!","-") -> - | I9: =IF(OR(E9=G9,F9=G9),"SAME BUCKET!","-") -> -
B10: Band 3 | C10: 5 & 6 | E10: ="["&'3 MinHash'!C73&"-"&'3 MinHash'!C74&"]" -> [1-3] | F10: ="["&'3 MinHash'!D73&"-"&'3 MinHash'!D74&"]" -> [1-1] | G10: ="["&'3 MinHash'!E73&"-"&'3 MinHash'!E74&"]" -> [2-2] | H10: =IF(E10=F10,"SAME BUCKET!","-") -> - | I10: =IF(OR(E10=G10,F10=G10),"SAME BUCKET!","-") -> -
B11: Band 4 | C11: 7 & 8 | E11: ="["&'3 MinHash'!C75&"-"&'3 MinHash'!C76&"]" -> [1-1] | F11: ="["&'3 MinHash'!D75&"-"&'3 MinHash'!D76&"]" -> [1-1] | G11: ="["&'3 MinHash'!E75&"-"&'3 MinHash'!E76&"]" -> [6-2] | H11: =IF(E11=F11,"SAME BUCKET!","-") -> SAME BUCKET! | I11: =IF(OR(E11=G11,F11=G11),"SAME BUCKET!","-") -> -
B13: Verdict
B14: Pair | C14: Candidate? | E14: Meaning
B15: S1 vs S2 | C15: =IF(COUNTIF(H8:H11,"SAME BUCKET!")>0,"YES - compare them","no") -> YES - compare them | E15: Band 4 caught the near-duplicates. One shared band is enough.
B16: anything vs S3 | C16: =IF(COUNTIF(I8:I11,"SAME BUCKET!")>0,"YES","no - never compared") -> no - never compared | E16: The dog sentence is skipped entirely - that skipped work is the whole speed-up.
B18: Why bands? The S-curve (live formulas: chance of becoming candidates vs true similarity)
B19: With 4 bands of 2, P(candidate) = 1-(1-s^2)^4. Dissimilar pairs almost never collide; similar pairs almost always do. The curve's steep step sits near 50% similarity - a tunable dial.
B21: True similarity s | C21: 1 shuffle alone: P=s | D21: 4 bands of 2: P=1-(1-s^2)^4
B22: 0 | C22: =B22 -> 0 | D22: =1-(1-B22^2)^4 -> 0
B23: 0.05 | C23: =B23 -> 0.05 | D23: =1-(1-B23^2)^4 -> 0.0099625625
B24: 0.1 | C24: =B24 -> 0.1 | D24: =1-(1-B24^2)^4 -> 0.03940399
B25: 0.15 | C25: =B25 -> 0.15 | D25: =1-(1-B25^2)^4 -> 0.087007806
B26: 0.2 | C26: =B26 -> 0.2 | D26: =1-(1-B26^2)^4 -> 0.15065344
B27: 0.25 | C27: =B27 -> 0.25 | D27: =1-(1-B27^2)^4 -> 0.2275238
B28: 0.3 | C28: =B28 -> 0.3 | D28: =1-(1-B28^2)^4 -> 0.31425039
B29: 0.35 | C29: =B29 -> 0.35 | D29: =1-(1-B29^2)^4 -> 0.40709037
B30: 0.4 | C30: =B30 -> 0.4 | D30: =1-(1-B30^2)^4 -> 0.50212864
B31: 0.45 | C31: =B31 -> 0.45 | D31: =1-(1-B31^2)^4 -> 0.59549605
B32: 0.5 | C32: =B32 -> 0.5 | D32: =1-(1-B32^2)^4 -> 0.68359375
B33: 0.55 | C33: =B33 -> 0.55 | D33: =1-(1-B33^2)^4 -> 0.76331167
... B42: 1 | C42: =B42 -> 1 | D42: =1-(1-B42^2)^4 -> 1
